[2025-02-08T19:01:06.767+0000] {local_task_job_runner.py:123} INFO - ::group::Pre task execution logs
[2025-02-08T19:01:06.782+0000] {taskinstance.py:2612} INFO - Dependencies all met for dep_context=non-requeueable deps ti=<TaskInstance: account_dim_gen.generate_account_dim_data scheduled__2025-01-15T00:00:00+00:00 [queued]>
[2025-02-08T19:01:06.792+0000] {taskinstance.py:2612} INFO - Dependencies all met for dep_context=requeueable deps ti=<TaskInstance: account_dim_gen.generate_account_dim_data scheduled__2025-01-15T00:00:00+00:00 [queued]>
[2025-02-08T19:01:06.792+0000] {taskinstance.py:2865} INFO - Starting attempt 1 of 1
[2025-02-08T19:01:06.804+0000] {taskinstance.py:2888} INFO - Executing <Task(PythonOperator): generate_account_dim_data> on 2025-01-15 00:00:00+00:00
[2025-02-08T19:01:06.811+0000] {logging_mixin.py:190} WARNING - /home/***/.local/lib/python3.12/site-packages/***/task/task_runner/standard_task_runner.py:70 DeprecationWarning: This process (pid=1007) is multi-threaded, use of fork() may lead to deadlocks in the child.
[2025-02-08T19:01:06.812+0000] {standard_task_runner.py:72} INFO - Started process 1017 to run task
[2025-02-08T19:01:06.812+0000] {standard_task_runner.py:104} INFO - Running: ['***', 'tasks', 'run', 'account_dim_gen', 'generate_account_dim_data', 'scheduled__2025-01-15T00:00:00+00:00', '--job-id', '131', '--raw', '--subdir', 'DAGS_FOLDER/account_dim_gen.py', '--cfg-path', '/tmp/tmpc1aftaev']
[2025-02-08T19:01:06.814+0000] {standard_task_runner.py:105} INFO - Job 131: Subtask generate_account_dim_data
[2025-02-08T19:01:06.849+0000] {task_command.py:467} INFO - Running <TaskInstance: account_dim_gen.generate_account_dim_data scheduled__2025-01-15T00:00:00+00:00 [running]> on host 2c1cd59afcc0
[2025-02-08T19:01:06.920+0000] {taskinstance.py:3131} INFO - Exporting env vars: AIRFLOW_CTX_DAG_OWNER='Saleh' AIRFLOW_CTX_DAG_ID='account_dim_gen' AIRFLOW_CTX_TASK_ID='generate_account_dim_data' AIRFLOW_CTX_EXECUTION_DATE='2025-01-15T00:00:00+00:00' AIRFLOW_CTX_TRY_NUMBER='1' AIRFLOW_CTX_DAG_RUN_ID='scheduled__2025-01-15T00:00:00+00:00'
[2025-02-08T19:01:06.921+0000] {taskinstance.py:731} INFO - ::endgroup::
[2025-02-08T19:01:06.935+0000] {logging_mixin.py:190} INFO - CSV file ./account_dim_large_data.csv with 50 row has been generated successfully!
[2025-02-08T19:01:06.935+0000] {python.py:240} INFO - Done. Returned value was: None
[2025-02-08T19:01:06.942+0000] {taskinstance.py:340} INFO - ::group::Post task execution logs
[2025-02-08T19:01:06.943+0000] {taskinstance.py:352} INFO - Marking task as SUCCESS. dag_id=account_dim_gen, task_id=generate_account_dim_data, run_id=scheduled__2025-01-15T00:00:00+00:00, execution_date=20250115T000000, start_date=20250208T190106, end_date=20250208T190106
[2025-02-08T19:01:06.986+0000] {local_task_job_runner.py:266} INFO - Task exited with return code 0
[2025-02-08T19:01:06.998+0000] {taskinstance.py:3900} INFO - 0 downstream tasks scheduled from follow-on schedule check
[2025-02-08T19:01:07.000+0000] {local_task_job_runner.py:245} INFO - ::endgroup::
[2025-02-08T20:41:21.196+0000] {local_task_job_runner.py:123} INFO - ::group::Pre task execution logs
[2025-02-08T20:41:21.209+0000] {taskinstance.py:2612} INFO - Dependencies all met for dep_context=non-requeueable deps ti=<TaskInstance: account_dim_gen.generate_account_dim_data scheduled__2025-01-15T00:00:00+00:00 [queued]>
[2025-02-08T20:41:21.216+0000] {taskinstance.py:2612} INFO - Dependencies all met for dep_context=requeueable deps ti=<TaskInstance: account_dim_gen.generate_account_dim_data scheduled__2025-01-15T00:00:00+00:00 [queued]>
[2025-02-08T20:41:21.216+0000] {taskinstance.py:2865} INFO - Starting attempt 1 of 1
[2025-02-08T20:41:21.229+0000] {taskinstance.py:2888} INFO - Executing <Task(PythonOperator): generate_account_dim_data> on 2025-01-15 00:00:00+00:00
[2025-02-08T20:41:21.239+0000] {logging_mixin.py:190} WARNING - /home/***/.local/lib/python3.12/site-packages/***/task/task_runner/standard_task_runner.py:70 DeprecationWarning: This process (pid=2097) is multi-threaded, use of fork() may lead to deadlocks in the child.
[2025-02-08T20:41:21.240+0000] {standard_task_runner.py:72} INFO - Started process 2108 to run task
[2025-02-08T20:41:21.239+0000] {standard_task_runner.py:104} INFO - Running: ['***', 'tasks', 'run', 'account_dim_gen', 'generate_account_dim_data', 'scheduled__2025-01-15T00:00:00+00:00', '--job-id', '358', '--raw', '--subdir', 'DAGS_FOLDER/account_dim_gen.py', '--cfg-path', '/tmp/tmpwrc0agoe']
[2025-02-08T20:41:21.241+0000] {standard_task_runner.py:105} INFO - Job 358: Subtask generate_account_dim_data
[2025-02-08T20:41:21.282+0000] {task_command.py:467} INFO - Running <TaskInstance: account_dim_gen.generate_account_dim_data scheduled__2025-01-15T00:00:00+00:00 [running]> on host 7e959c1a2a8b
[2025-02-08T20:41:21.348+0000] {local_task_job_runner.py:127} ERROR - Received SIGTERM. Terminating subprocesses
[2025-02-08T20:41:21.351+0000] {process_utils.py:132} INFO - Sending 15 to group 2108. PIDs of all processes in the group: [2108]
[2025-02-08T20:41:21.351+0000] {process_utils.py:87} INFO - Sending the signal 15 to group 2108
[2025-02-08T20:41:21.352+0000] {taskinstance.py:3092} ERROR - Received SIGTERM. Terminating subprocesses.
[2025-02-08T20:41:21.362+0000] {taskinstance.py:3310} ERROR - Task failed with exception
Traceback (most recent call last):
  File "/home/airflow/.local/lib/python3.12/site-packages/sqlalchemy/sql/annotation.py", line 160, in __new__
    cls = annotated_classes[element.__class__]
          ~~~~~~~~~~~~~~~~~^^^^^^^^^^^^^^^^^^^
KeyError: <class 'sqlalchemy.sql.dml.Delete'>

During handling of the above exception, another exception occurred:

Traceback (most recent call last):
  File "/home/airflow/.local/lib/python3.12/site-packages/airflow/models/taskinstance.py", line 273, in _run_raw_task
    TaskInstance._execute_task_with_callbacks(
  File "/home/airflow/.local/lib/python3.12/site-packages/airflow/models/taskinstance.py", line 3122, in _execute_task_with_callbacks
    _update_rtif(ti=self, rendered_fields=rendered_fields)
  File "/home/airflow/.local/lib/python3.12/site-packages/airflow/api_internal/internal_api_call.py", line 139, in wrapper
    return func(*args, **kwargs)
           ^^^^^^^^^^^^^^^^^^^^^
  File "/home/airflow/.local/lib/python3.12/site-packages/airflow/utils/session.py", line 97, in wrapper
    return func(*args, session=session, **kwargs)
           ^^^^^^^^^^^^^^^^^^^^^^^^^^^^^^^^^^^^^^
  File "/home/airflow/.local/lib/python3.12/site-packages/airflow/models/taskinstance.py", line 1642, in _update_rtif
    RenderedTaskInstanceFields.delete_old_records(ti.task_id, ti.dag_id, session=session)
  File "/home/airflow/.local/lib/python3.12/site-packages/airflow/utils/session.py", line 94, in wrapper
    return func(*args, **kwargs)
           ^^^^^^^^^^^^^^^^^^^^^
  File "/home/airflow/.local/lib/python3.12/site-packages/airflow/models/renderedtifields.py", line 265, in delete_old_records
    cls._do_delete_old_records(
  File "/home/airflow/.local/lib/python3.12/site-packages/airflow/utils/retries.py", line 93, in wrapped_function
    for attempt in run_with_db_retries(max_retries=retries, logger=logger, **retry_kwargs):
                   ^^^^^^^^^^^^^^^^^^^^^^^^^^^^^^^^^^^^^^^^^^^^^^^^^^^^^^^^^^^^^^^^^^^^^^^
  File "/home/airflow/.local/lib/python3.12/site-packages/tenacity/__init__.py", line 443, in __iter__
    do = self.iter(retry_state=retry_state)
         ^^^^^^^^^^^^^^^^^^^^^^^^^^^^^^^^^^
  File "/home/airflow/.local/lib/python3.12/site-packages/tenacity/__init__.py", line 376, in iter
    result = action(retry_state)
             ^^^^^^^^^^^^^^^^^^^
  File "/home/airflow/.local/lib/python3.12/site-packages/tenacity/__init__.py", line 398, in <lambda>
    self._add_action_func(lambda rs: rs.outcome.result())
                                     ^^^^^^^^^^^^^^^^^^^
  File "/usr/local/lib/python3.12/concurrent/futures/_base.py", line 449, in result
    return self.__get_result()
           ^^^^^^^^^^^^^^^^^^^
  File "/usr/local/lib/python3.12/concurrent/futures/_base.py", line 401, in __get_result
    raise self._exception
  File "/home/airflow/.local/lib/python3.12/site-packages/airflow/utils/retries.py", line 102, in wrapped_function
    return func(*args, **kwargs)
           ^^^^^^^^^^^^^^^^^^^^^
  File "/home/airflow/.local/lib/python3.12/site-packages/airflow/models/renderedtifields.py", line 299, in _do_delete_old_records
    session.execute(stmt)
  File "/home/airflow/.local/lib/python3.12/site-packages/sqlalchemy/orm/session.py", line 1665, in execute
    ) = compile_state_cls.orm_pre_session_exec(
        ^^^^^^^^^^^^^^^^^^^^^^^^^^^^^^^^^^^^^^^
  File "/home/airflow/.local/lib/python3.12/site-packages/sqlalchemy/orm/persistence.py", line 1831, in orm_pre_session_exec
    statement = statement._annotate(
                ^^^^^^^^^^^^^^^^^^^^
  File "/home/airflow/.local/lib/python3.12/site-packages/sqlalchemy/sql/annotation.py", line 104, in _annotate
    return Annotated(self, values)
           ^^^^^^^^^^^^^^^^^^^^^^^
  File "/home/airflow/.local/lib/python3.12/site-packages/sqlalchemy/sql/annotation.py", line 162, in __new__
    cls = _new_annotation_type(element.__class__, cls)
          ^^^^^^^^^^^^^^^^^^^^^^^^^^^^^^^^^^^^^^^^^^^^
  File "/home/airflow/.local/lib/python3.12/site-packages/sqlalchemy/sql/annotation.py", line 352, in _new_annotation_type
    if super_ in annotated_classes:
       ^^^^^^^^^^^^^^^^^^^^^^^^^^^
  File "/home/airflow/.local/lib/python3.12/site-packages/airflow/models/taskinstance.py", line 3094, in signal_handler
    raise AirflowTaskTerminated("Task received SIGTERM signal")
airflow.exceptions.AirflowTaskTerminated: Task received SIGTERM signal
[2025-02-08T20:41:21.368+0000] {taskinstance.py:1225} INFO - Marking task as FAILED. dag_id=account_dim_gen, task_id=generate_account_dim_data, run_id=scheduled__2025-01-15T00:00:00+00:00, execution_date=20250115T000000, start_date=20250208T204121, end_date=20250208T204121
[2025-02-08T20:41:21.385+0000] {taskinstance.py:340} INFO - ::group::Post task execution logs
[2025-02-08T20:41:21.404+0000] {process_utils.py:80} INFO - Process psutil.Process(pid=2108, status='terminated', exitcode=2, started='20:41:21') (2108) terminated with exit code 2
[2025-02-08T20:41:21.405+0000] {local_task_job_runner.py:266} INFO - Task exited with return code 143
[2025-02-08T20:41:21.427+0000] {taskinstance.py:3900} INFO - 0 downstream tasks scheduled from follow-on schedule check
[2025-02-08T20:41:23.151+0000] {local_task_job_runner.py:127} ERROR - Received SIGTERM. Terminating subprocesses
[2025-02-08T20:41:23.151+0000] {local_task_job_runner.py:266} INFO - Task exited with return code 143
